[2025-06-08T18:48:16.021+0000] {taskinstance.py:1956} INFO - Dependencies all met for dep_context=non-requeueable deps ti=<TaskInstance: update_daily_data_dag.exploitation_delta_tables_task manual__2025-06-08T18:47:16.278881+00:00 [queued]>
[2025-06-08T18:48:16.038+0000] {taskinstance.py:1956} INFO - Dependencies all met for dep_context=requeueable deps ti=<TaskInstance: update_daily_data_dag.exploitation_delta_tables_task manual__2025-06-08T18:47:16.278881+00:00 [queued]>
[2025-06-08T18:48:16.040+0000] {taskinstance.py:2170} INFO - Starting attempt 1 of 1
[2025-06-08T18:48:16.070+0000] {taskinstance.py:2191} INFO - Executing <Task(PythonOperator): exploitation_delta_tables_task> on 2025-06-08 18:47:16.278881+00:00
[2025-06-08T18:48:16.079+0000] {standard_task_runner.py:60} INFO - Started process 682 to run task
[2025-06-08T18:48:16.084+0000] {standard_task_runner.py:87} INFO - Running: ['***', 'tasks', 'run', 'update_daily_data_dag', 'exploitation_delta_tables_task', 'manual__2025-06-08T18:47:16.278881+00:00', '--job-id', '40', '--raw', '--subdir', 'DAGS_FOLDER/scheduled_task.py', '--cfg-path', '/tmp/tmp6e_wl9f0']
[2025-06-08T18:48:16.089+0000] {standard_task_runner.py:88} INFO - Job 40: Subtask exploitation_delta_tables_task
[2025-06-08T18:48:16.115+0000] {logging_mixin.py:188} WARNING - /home/***/.local/lib/python3.10/site-packages/***/settings.py:194 DeprecationWarning: The sql_alchemy_conn option in [core] has been moved to the sql_alchemy_conn option in [database] - the old setting has been used, but please update your config.
[2025-06-08T18:48:16.164+0000] {task_command.py:423} INFO - Running <TaskInstance: update_daily_data_dag.exploitation_delta_tables_task manual__2025-06-08T18:47:16.278881+00:00 [running]> on host 7d0db884b06d
[2025-06-08T18:48:16.317+0000] {taskinstance.py:2480} INFO - Exporting env vars: AIRFLOW_CTX_DAG_OWNER='***' AIRFLOW_CTX_DAG_ID='update_daily_data_dag' AIRFLOW_CTX_TASK_ID='exploitation_delta_tables_task' AIRFLOW_CTX_EXECUTION_DATE='2025-06-08T18:47:16.278881+00:00' AIRFLOW_CTX_TRY_NUMBER='1' AIRFLOW_CTX_DAG_RUN_ID='manual__2025-06-08T18:47:16.278881+00:00'
[2025-06-08T18:48:26.485+0000] {local_task_job_runner.py:302} WARNING - State of this instance has been externally set to upstream_failed. Terminating instance.
[2025-06-08T18:48:26.488+0000] {process_utils.py:131} INFO - Sending 15 to group 682. PIDs of all processes in the group: [683, 682]
[2025-06-08T18:48:26.488+0000] {process_utils.py:86} INFO - Sending the signal 15 to group 682
[2025-06-08T18:48:26.488+0000] {taskinstance.py:2450} ERROR - Received SIGTERM. Terminating subprocesses.
[2025-06-08T18:48:26.489+0000] {clientserver.py:538} INFO - Error while receiving.
Traceback (most recent call last):
  File "/home/airflow/.local/lib/python3.10/site-packages/py4j/clientserver.py", line 511, in send_command
    answer = smart_decode(self.stream.readline()[:-1])
  File "/usr/local/lib/python3.10/socket.py", line 705, in readinto
    return self._sock.recv_into(b)
  File "/home/airflow/.local/lib/python3.10/site-packages/airflow/models/taskinstance.py", line 2452, in signal_handler
    raise AirflowException("Task received SIGTERM signal")
airflow.exceptions.AirflowException: Task received SIGTERM signal
[2025-06-08T18:48:26.490+0000] {clientserver.py:543} INFO - Closing down clientserver connection
[2025-06-08T18:48:26.491+0000] {java_gateway.py:1055} ERROR - Exception while sending command.
Traceback (most recent call last):
  File "/home/airflow/.local/lib/python3.10/site-packages/py4j/clientserver.py", line 511, in send_command
    answer = smart_decode(self.stream.readline()[:-1])
  File "/usr/local/lib/python3.10/socket.py", line 705, in readinto
    return self._sock.recv_into(b)
  File "/home/airflow/.local/lib/python3.10/site-packages/airflow/models/taskinstance.py", line 2452, in signal_handler
    raise AirflowException("Task received SIGTERM signal")
airflow.exceptions.AirflowException: Task received SIGTERM signal

During handling of the above exception, another exception occurred:

Traceback (most recent call last):
  File "/home/airflow/.local/lib/python3.10/site-packages/py4j/java_gateway.py", line 1038, in send_command
    response = connection.send_command(command)
  File "/home/airflow/.local/lib/python3.10/site-packages/py4j/clientserver.py", line 539, in send_command
    raise Py4JNetworkError(
py4j.protocol.Py4JNetworkError: Error while sending or receiving
[2025-06-08T18:48:26.492+0000] {clientserver.py:543} INFO - Closing down clientserver connection
[2025-06-08T18:48:26.492+0000] {logging_mixin.py:188} INFO - Error: org.apache.spark.sql.SparkSession.getDefaultSession does not exist in the JVM
[2025-06-08T18:48:26.492+0000] {python.py:201} INFO - Done. Returned value was: False
[2025-06-08T18:48:26.622+0000] {taskinstance.py:1138} INFO - Marking task as SUCCESS. dag_id=update_daily_data_dag, task_id=exploitation_delta_tables_task, execution_date=20250608T184716, start_date=20250608T184816, end_date=20250608T184826
[2025-06-08T18:48:26.742+0000] {process_utils.py:79} INFO - Process psutil.Process(pid=682, status='terminated', exitcode=0, started='18:48:15') (682) terminated with exit code 0
[2025-06-08T18:48:27.276+0000] {process_utils.py:79} INFO - Process psutil.Process(pid=683, status='terminated', started='18:48:16') (683) terminated with exit code None
