[2025-06-08T18:47:17.864+0000] {taskinstance.py:1956} INFO - Dependencies all met for dep_context=non-requeueable deps ti=<TaskInstance: update_daily_data_dag.trusted_delta_tables_task manual__2025-06-08T18:47:16.278881+00:00 [queued]>
[2025-06-08T18:47:17.872+0000] {taskinstance.py:1956} INFO - Dependencies all met for dep_context=requeueable deps ti=<TaskInstance: update_daily_data_dag.trusted_delta_tables_task manual__2025-06-08T18:47:16.278881+00:00 [queued]>
[2025-06-08T18:47:17.873+0000] {taskinstance.py:2170} INFO - Starting attempt 1 of 1
[2025-06-08T18:47:17.885+0000] {taskinstance.py:2191} INFO - Executing <Task(PythonOperator): trusted_delta_tables_task> on 2025-06-08 18:47:16.278881+00:00
[2025-06-08T18:47:17.889+0000] {standard_task_runner.py:60} INFO - Started process 195 to run task
[2025-06-08T18:47:17.892+0000] {standard_task_runner.py:87} INFO - Running: ['***', 'tasks', 'run', 'update_daily_data_dag', 'trusted_delta_tables_task', 'manual__2025-06-08T18:47:16.278881+00:00', '--job-id', '39', '--raw', '--subdir', 'DAGS_FOLDER/scheduled_task.py', '--cfg-path', '/tmp/tmp7ncbja7p']
[2025-06-08T18:47:17.895+0000] {standard_task_runner.py:88} INFO - Job 39: Subtask trusted_delta_tables_task
[2025-06-08T18:47:17.909+0000] {logging_mixin.py:188} WARNING - /home/***/.local/lib/python3.10/site-packages/***/settings.py:194 DeprecationWarning: The sql_alchemy_conn option in [core] has been moved to the sql_alchemy_conn option in [database] - the old setting has been used, but please update your config.
[2025-06-08T18:47:17.942+0000] {task_command.py:423} INFO - Running <TaskInstance: update_daily_data_dag.trusted_delta_tables_task manual__2025-06-08T18:47:16.278881+00:00 [running]> on host 7d0db884b06d
[2025-06-08T18:47:18.029+0000] {taskinstance.py:2480} INFO - Exporting env vars: AIRFLOW_CTX_DAG_OWNER='***' AIRFLOW_CTX_DAG_ID='update_daily_data_dag' AIRFLOW_CTX_TASK_ID='trusted_delta_tables_task' AIRFLOW_CTX_EXECUTION_DATE='2025-06-08T18:47:16.278881+00:00' AIRFLOW_CTX_TRY_NUMBER='1' AIRFLOW_CTX_DAG_RUN_ID='manual__2025-06-08T18:47:16.278881+00:00'
[2025-06-08T18:48:13.781+0000] {local_task_job_runner.py:302} WARNING - State of this instance has been externally set to restarting. Terminating instance.
[2025-06-08T18:48:13.847+0000] {process_utils.py:131} INFO - Sending 15 to group 195. PIDs of all processes in the group: [196, 195]
[2025-06-08T18:48:13.848+0000] {process_utils.py:86} INFO - Sending the signal 15 to group 195
[2025-06-08T18:48:13.854+0000] {taskinstance.py:2450} ERROR - Received SIGTERM. Terminating subprocesses.
[2025-06-08T18:48:13.876+0000] {clientserver.py:538} INFO - Error while receiving.
Traceback (most recent call last):
  File "/home/airflow/.local/lib/python3.10/site-packages/py4j/clientserver.py", line 511, in send_command
    answer = smart_decode(self.stream.readline()[:-1])
  File "/usr/local/lib/python3.10/socket.py", line 705, in readinto
    return self._sock.recv_into(b)
  File "/home/airflow/.local/lib/python3.10/site-packages/airflow/models/taskinstance.py", line 2452, in signal_handler
    raise AirflowException("Task received SIGTERM signal")
airflow.exceptions.AirflowException: Task received SIGTERM signal
[2025-06-08T18:48:13.894+0000] {clientserver.py:543} INFO - Closing down clientserver connection
[2025-06-08T18:48:13.898+0000] {java_gateway.py:1055} ERROR - Exception while sending command.
Traceback (most recent call last):
  File "/home/airflow/.local/lib/python3.10/site-packages/py4j/clientserver.py", line 511, in send_command
    answer = smart_decode(self.stream.readline()[:-1])
  File "/usr/local/lib/python3.10/socket.py", line 705, in readinto
    return self._sock.recv_into(b)
  File "/home/airflow/.local/lib/python3.10/site-packages/airflow/models/taskinstance.py", line 2452, in signal_handler
    raise AirflowException("Task received SIGTERM signal")
airflow.exceptions.AirflowException: Task received SIGTERM signal

During handling of the above exception, another exception occurred:

Traceback (most recent call last):
  File "/home/airflow/.local/lib/python3.10/site-packages/py4j/java_gateway.py", line 1038, in send_command
    response = connection.send_command(command)
  File "/home/airflow/.local/lib/python3.10/site-packages/py4j/clientserver.py", line 539, in send_command
    raise Py4JNetworkError(
py4j.protocol.Py4JNetworkError: Error while sending or receiving
[2025-06-08T18:48:13.902+0000] {clientserver.py:543} INFO - Closing down clientserver connection
[2025-06-08T18:48:13.905+0000] {logging_mixin.py:188} INFO - Error: An error occurred while calling o194.save
[2025-06-08T18:48:13.908+0000] {python.py:201} INFO - Done. Returned value was: False
[2025-06-08T18:48:14.116+0000] {taskinstance.py:1138} INFO - Marking task as SUCCESS. dag_id=update_daily_data_dag, task_id=trusted_delta_tables_task, execution_date=20250608T184716, start_date=20250608T184717, end_date=20250608T184814
[2025-06-08T18:48:14.183+0000] {process_utils.py:79} INFO - Process psutil.Process(pid=195, status='terminated', exitcode=0, started='18:47:17') (195) terminated with exit code 0
[2025-06-08T18:48:14.518+0000] {process_utils.py:79} INFO - Process psutil.Process(pid=196, status='terminated', started='18:47:17') (196) terminated with exit code None
